<?xml version="1.0" encoding="utf-8"?>
<!-- This URDF was automatically created by SolidWorks to URDF Exporter! Originally created by Stephen Brawner (brawner@gmail.com) 
     Commit Version: 1.6.0-1-g15f4949  Build Version: 1.6.7594.29634
     For more information, please see http://wiki.ros.org/sw_urdf_exporter -->
<robot
  name="broken_feet">
  <link
    name="body">
    <inertial>
      <origin
        xyz="-9.54880772585182E-07 0.0464116058279854 0.0121268540557259"
        rpy="0 0 0" />
      <mass
        value="1.03" />
      <inertia
        ixx="0.00247370771659153"
        ixy="1.75628213090658E-08"
        ixz="1.38332715720516E-08"
        iyy="0.00245934745224797"
        iyz="-3.59628508890605E-08"
        izz="0.00248312387112852" />
    </inertial>
    <visual>
      <origin
        xyz="0 0 0"
        rpy="0 0 0" />
      <geometry>
        <mesh
          filename="package://broken_feet/meshes/body.STL" />
      </geometry>
      <material
        name="">
        <color
          rgba="0.2 0.2 0.2 1" />
      </material>
    </visual>
    <collision>
      <origin
        xyz="0 0 0"
        rpy="0 0 0" />
      <geometry>
        <mesh
          filename="package://broken_feet/meshes/body.STL" />
      </geometry>
    </collision>
  </link>
  <link
    name="00">
    <inertial>
      <origin
        xyz="-0.0440388898017557 -3.63001309726385E-07 0.0577248764406495"
        rpy="0 0 0" />
      <mass
        value="0.085" />
      <inertia
        ixx="7.62606139414576E-05"
        ixy="1.36848294672652E-14"
        ixz="-6.41822721014909E-10"
        iyy="7.58096552667324E-05"
        iyz="-6.41822721063825E-10"
        izz="3.22965690401587E-05" />
    </inertial>
    <visual>
      <origin
        xyz="0 0 0"
        rpy="0 0 0" />
      <geometry>
        <mesh
          filename="package://broken_feet/meshes/00.STL" />
      </geometry>
      <material
        name="">
        <color
          rgba="0.792156862745098 0.819607843137255 0.933333333333333 1" />
      </material>
    </visual>
    <collision>
      <origin
        xyz="0 0 0"
        rpy="0 0 0" />
      <geometry>
        <mesh
          filename="package://broken_feet/meshes/00.STL" />
      </geometry>
    </collision>
  </link>
  <joint
    name="body_00"
    type="revolute">
    <origin
      xyz="-0.0698576418528583 -0.0961507619254144 -0.0118567866274084"
      rpy="-3.10154214245784 1.38208579601134 0.942477796076948" />
    <parent
      link="body" />
    <child
      link="00" />
    <axis
      xyz="1 0 0" />
    <limit
      lower="-4"
      upper="4"
      effort="2"
      velocity="0.2094396" />
  </joint>
  <link
    name="01">
    <inertial>
      <origin
        xyz="-1.4520052390582E-06 -1.45200523908595E-06 0.0577259654445788"
        rpy="0 0 0" />
      <mass
        value="0.103853927874307" />
      <inertia
        ixx="6.67941659320179E-05"
        ixy="2.18957246912288E-13"
        ixz="-2.79364977315509E-09"
        iyy="8.52661387999373E-05"
        iyz="-2.79364977318643E-09"
        izz="3.22965686296139E-05" />
    </inertial>
    <visual>
      <origin
        xyz="0 0 0"
        rpy="0 0 0" />
      <geometry>
        <mesh
          filename="package://broken_feet/meshes/01.STL" />
      </geometry>
      <material
        name="">
        <color
          rgba="0.792156862745098 0.819607843137255 0.933333333333333 1" />
      </material>
    </visual>
    <collision>
      <origin
        xyz="0 0 0"
        rpy="0 0 0" />
      <geometry>
        <mesh
          filename="package://broken_feet/meshes/01.STL" />
      </geometry>
    </collision>
  </link>
  <joint
    name="00_01"
    type="revolute">
    <origin
      xyz="-0.0440385268004459 0 0.0812000000000013"
      rpy="0 0 1.5707963267949" />
    <parent
      link="00" />
    <child
      link="01" />
    <axis
      xyz="1 0 0" />
      <limit
      lower="-4"
      upper="4"
      effort="2"
      velocity="0.2094396" />
  </joint>
  <link
    name="02">
    <inertial>
      <origin
        xyz="2.77555756156289E-17 -0.0157761500765907 0.0474773983105136"
        rpy="0 0 0" />
      <mass
        value="0.141254271685154" />
      <inertia
        ixx="0.000416559633615452"
        ixy="-1.66018457661843E-19"
        ixz="9.48676900924816E-20"
        iyy="5.44190175587167E-05"
        iyz="6.08030153794323E-05"
        izz="0.000394411456477929" />
    </inertial>
    <visual>
      <origin
        xyz="0 0 0"
        rpy="0 0 0" />
      <geometry>
        <mesh
          filename="package://broken_feet/meshes/32.STL" />
      </geometry>
      <material
        name="">
        <color
          rgba="0.792156862745098 0.819607843137255 0.933333333333333 1" />
      </material>
    </visual>
    <collision>
      <origin
        xyz="0 0 0"
        rpy="0 0 0" />
      <geometry>
        <mesh
          filename="package://broken_feet/meshes/32.STL" />
      </geometry>
    </collision>
  </link>
  <joint
    name="01_02"
    type="revolute">
    <origin
      xyz="0 0 0.0812000000000015"
      rpy="0 0 0" />
    <parent
      link="01" />
    <child
      link="02" />
    <axis
      xyz="1 0 0" />
      <limit
      lower="-4"
      upper="4"
      effort="2"
      velocity="0.2094396" />
  </joint>
  <link
    name="10">
    <inertial>
      <origin
        xyz="-0.0267710126538516 -3.63001309733324E-07 0.0577248764406495"
        rpy="0 0 0" />
      <mass
        value="0.103853927874307" />
      <inertia
        ixx="7.62606139414575E-05"
        ixy="1.36848345494629E-14"
        ixz="-6.41822721017132E-10"
        iyy="7.58096552667324E-05"
        iyz="-6.41822721072295E-10"
        izz="3.22965690401587E-05" />
    </inertial>
    <visual>
      <origin
        xyz="0 0 0"
        rpy="0 0 0" />
      <geometry>
        <mesh
          filename="package://broken_feet/meshes/10.STL" />
      </geometry>
      <material
        name="">
        <color
          rgba="0.792156862745098 0.819607843137255 0.933333333333333 1" />
      </material>
    </visual>
    <collision>
      <origin
        xyz="0 0 0"
        rpy="0 0 0" />
      <geometry>
        <mesh
          filename="package://broken_feet/meshes/10.STL" />
      </geometry>
    </collision>
  </link>
  <joint
    name="body_10"
    type="revolute">
    <origin
      xyz="-0.116112807904595 0.0377273413418564 0.00510453297153173"
      rpy="-3.14159265358979 1.38208579601134 -0.314159265358966" />
    <parent
      link="body" />
    <child
      link="10" />
    <axis
      xyz="1 0 0" />
    <limit
      lower="-4"
      upper="4"
      effort="2"
      velocity="0.2094396" />
  </joint>
  <link
    name="11">
    <inertial>
      <origin
        xyz="-1.45200523908595E-06 -1.45200523906514E-06 0.0577259654445788"
        rpy="0 0 0" />
      <mass
        value="0.103853927874307" />
      <inertia
        ixx="6.6794165932018E-05"
        ixy="2.18957269993935E-13"
        ixz="-2.79364977317373E-09"
        iyy="8.52661387999373E-05"
        iyz="-2.79364977317876E-09"
        izz="3.2296568629614E-05" />
    </inertial>
    <visual>
      <origin
        xyz="0 0 0"
        rpy="0 0 0" />
      <geometry>
        <mesh
          filename="package://broken_feet/meshes/11.STL" />
      </geometry>
      <material
        name="">
        <color
          rgba="0.792156862745098 0.819607843137255 0.933333333333333 1" />
      </material>
    </visual>
    <collision>
      <origin
        xyz="0 0 0"
        rpy="0 0 0" />
      <geometry>
        <mesh
          filename="package://broken_feet/meshes/11.STL" />
      </geometry>
    </collision>
  </link>
  <joint
    name="10_11"
    type="revolute">
    <origin
      xyz="-0.0267706496525418 0 0.0812"
      rpy="0 0 1.5707963267949" />
    <parent
      link="10" />
    <child
      link="11" />
    <axis
      xyz="1 0 0" />
      <limit
      lower="-4"
      upper="4"
      effort="2"
      velocity="0.2094396" />
  </joint>
  <link
    name="12">
    <inertial>
      <origin
        xyz="-1.11022302462516E-16 -0.0532160764699449 0.0531179899870652"
        rpy="0 0 0" />
      <mass
        value="0.141254271685154" />
      <inertia
        ixx="0.000416559633615451"
        ixy="-4.01493616998538E-19"
        ixz="6.7762635780344E-20"
        iyy="5.44190175587165E-05"
        iyz="6.08030153794321E-05"
        izz="0.000394411456477929" />
    </inertial>
    <visual>
      <origin
        xyz="0 0 0"
        rpy="0 0 0" />
      <geometry>
        <mesh
          filename="package://broken_feet/meshes/12.STL" />
      </geometry>
      <material
        name="">
        <color
          rgba="0.792156862745098 0.819607843137255 0.933333333333333 1" />
      </material>
    </visual>
    <collision>
      <origin
        xyz="0 0 0"
        rpy="0 0 0" />
      <geometry>
        <mesh
          filename="package://broken_feet/meshes/12.STL" />
      </geometry>
    </collision>
  </link>
  <joint
    name="11_12"
    type="revolute">
    <origin
      xyz="0 0 0.0812"
      rpy="0 0 0" />
    <parent
      link="11" />
    <child
      link="12" />
    <axis
      xyz="1 0 0" />
      <limit
      lower="-4"
      upper="4"
      effort="2"
      velocity="0.2094396" />
  </joint>
  <link
    name="20">
    <inertial>
      <origin
        xyz="-0.0496583686279049 -3.63001309788835E-07 0.0577248764406495"
        rpy="0 0 0" />
      <mass
        value="0.103853927874307" />
      <inertia
        ixx="7.62606139414576E-05"
        ixy="1.36848277731993E-14"
        ixz="-6.41822721029838E-10"
        iyy="7.58096552667325E-05"
        iyz="-6.41822721044343E-10"
        izz="3.22965690401588E-05" />
    </inertial>
    <visual>
      <origin
        xyz="0 0 0"
        rpy="0 0 0" />
      <geometry>
        <mesh
          filename="package://broken_feet/meshes/20.STL" />
      </geometry>
      <material
        name="">
        <color
          rgba="0.792156862745098 0.819607843137255 0.933333333333333 1" />
      </material>
    </visual>
    <collision>
      <origin
        xyz="0 0 0"
        rpy="0 0 0" />
      <geometry>
        <mesh
          filename="package://broken_feet/meshes/20.STL" />
      </geometry>
    </collision>
  </link>
  <joint
    name="body_20"
    type="revolute">
    <origin
      xyz="0.112029450810574 0.0364005781952566 -0.0173765025446221"
      rpy="-3.11057360693529 1.38208579601134 -2.82743338823083" />
    <parent
      link="body" />
    <child
      link="20" />
    <axis
      xyz="1 0 0" />
    <limit
      lower="-4"
      upper="4"
      effort="2"
      velocity="0.2094396" />
  </joint>
  <link
    name="21">
    <inertial>
      <origin
        xyz="-1.45200523912065E-06 -1.45200523907901E-06 0.0577259654445788"
        rpy="0 0 0" />
      <mass
        value="0.103853927874307" />
      <inertia
        ixx="6.6794165932018E-05"
        ixy="2.18957261735364E-13"
        ixz="-2.79364977315933E-09"
        iyy="8.52661387999373E-05"
        iyz="-2.79364977319967E-09"
        izz="3.2296568629614E-05" />
    </inertial>
    <visual>
      <origin
        xyz="0 0 0"
        rpy="0 0 0" />
      <geometry>
        <mesh
          filename="package://broken_feet/meshes/21.STL" />
      </geometry>
      <material
        name="">
        <color
          rgba="0.792156862745098 0.819607843137255 0.933333333333333 1" />
      </material>
    </visual>
    <collision>
      <origin
        xyz="0 0 0"
        rpy="0 0 0" />
      <geometry>
        <mesh
          filename="package://broken_feet/meshes/21.STL" />
      </geometry>
    </collision>
  </link>
  <joint
    name="20_21"
    type="revolute">
    <origin
      xyz="-0.0496580056265952 0 0.0812000000000004"
      rpy="0 0 1.5707963267949" />
    <parent
      link="20" />
    <child
      link="21" />
    <axis
      xyz="1 0 0" />
      <limit
      lower="-4"
      upper="4"
      effort="2"
      velocity="0.2094396" />
  </joint>
  <link
    name="22">
    <inertial>
      <origin
        xyz="1.38777878078145E-16 -0.0532160764699448 0.0531179899870652"
        rpy="0 0 0" />
      <mass
        value="0.141254271685154" />
      <inertia
        ixx="0.000416559633615452"
        ixy="2.01593841446523E-19"
        ixz="-2.03287907341032E-20"
        iyy="5.44190175587168E-05"
        iyz="6.08030153794327E-05"
        izz="0.000394411456477929" />
    </inertial>
    <visual>
      <origin
        xyz="0 0 0"
        rpy="0 0 0" />
      <geometry>
        <mesh
          filename="package://broken_feet/meshes/22.STL" />
      </geometry>
      <material
        name="">
        <color
          rgba="0.792156862745098 0.819607843137255 0.933333333333333 1" />
      </material>
    </visual>
    <collision>
      <origin
        xyz="0 0 0"
        rpy="0 0 0" />
      <geometry>
        <mesh
          filename="package://broken_feet/meshes/22.STL" />
      </geometry>
    </collision>
  </link>
  <joint
    name="21_22"
    type="revolute">
    <origin
      xyz="0 0 0.0812000000000002"
      rpy="0 0 0" />
    <parent
      link="21" />
    <child
      link="22" />
    <axis
      xyz="1 0 0" />
      <limit
      lower="-4"
      upper="4"
      effort="2"
      velocity="0.2094396" />
  </joint>
  <link
    name="30">
    <inertial>
      <origin
        xyz="-0.0565268730517737 -3.63001309802713E-07 0.0577248764406495"
        rpy="0 0 0" />
      <mass
        value="0.103853927874307" />
      <inertia
        ixx="7.62606139414577E-05"
        ixy="1.36848260791334E-14"
        ixz="-6.41822721030791E-10"
        iyy="7.58096552667325E-05"
        iyz="-6.41822721038414E-10"
        izz="3.22965690401588E-05" />
    </inertial>
    <visual>
      <origin
        xyz="0 0 0"
        rpy="0 0 0" />
      <geometry>
        <mesh
          filename="package://broken_feet/meshes/30.STL" />
      </geometry>
      <material
        name="">
        <color
          rgba="0.792156862745098 0.819607843137255 0.933333333333333 1" />
      </material>
    </visual>
    <collision>
      <origin
        xyz="0 0 0"
        rpy="0 0 0" />
      <geometry>
        <mesh
          filename="package://broken_feet/meshes/30.STL" />
      </geometry>
    </collision>
  </link>
  <joint
    name="body_30"
    type="revolute">
    <origin
      xyz="0.068480665747503 -0.0942555169090825 -0.0241230700411436"
      rpy="-3.09184703655275 1.38208579601134 2.19911485751285" />
    <parent
      link="body" />
    <child
      link="30" />
    <axis
      xyz="1 0 0" />
    <limit
      lower="-4"
      upper="4"
      effort="2"
      velocity="0.2094396" />
  </joint>
  <link
    name="31">
    <inertial>
      <origin
        xyz="-1.45200523912759E-06 -1.45200523904432E-06 0.0577259654445788"
        rpy="0 0 0" />
      <mass
        value="0.103853927874307" />
      <inertia
        ixx="6.67941659320179E-05"
        ixy="2.18957272746792E-13"
        ixz="-2.79364977314323E-09"
        iyy="8.52661387999372E-05"
        iyz="-2.7936497731966E-09"
        izz="3.22965686296139E-05" />
    </inertial>
    <visual>
      <origin
        xyz="0 0 0"
        rpy="0 0 0" />
      <geometry>
        <mesh
          filename="package://broken_feet/meshes/31.STL" />
      </geometry>
      <material
        name="">
        <color
          rgba="0.792156862745098 0.819607843137255 0.933333333333333 1" />
      </material>
    </visual>
    <collision>
      <origin
        xyz="0 0 0"
        rpy="0 0 0" />
      <geometry>
        <mesh
          filename="package://broken_feet/meshes/31.STL" />
      </geometry>
    </collision>
  </link>
  <joint
    name="30_31"
    type="revolute">
    <origin
      xyz="-0.0565265100504638 0 0.0812000000000006"
      rpy="0 0 1.5707963267949" />
    <parent
      link="30" />
    <child
      link="31" />
    <axis
      xyz="1 0 0" />
      <limit
      lower="-4"
      upper="4"
      effort="2"
      velocity="0.2094396" />
  </joint>
  <link
    name="32">
    <inertial>
      <origin
        xyz="5.55111512312578E-17 -0.0532160764699448 0.0531179899870653"
        rpy="0 0 0" />
      <mass
        value="0.0831925653721974" />
      <inertia
        ixx="6.18699908273782E-05"
        ixy="2.5410988417629E-21"
        ixz="1.01643953670516E-20"
        iyy="4.2825711220069E-05"
        iyz="1.80609050865785E-05"
        izz="4.61612171497649E-05" />
    </inertial>
    <visual>
      <origin
        xyz="0 0 0"
        rpy="0 0 0" />
      <geometry>
        <mesh
          filename="package://broken_feet/meshes/02.STL" />
      </geometry>
      <material
        name="">
        <color
          rgba="0.792156862745098 0.819607843137255 0.933333333333333 1" />
      </material>
    </visual>
    <collision>
      <origin
        xyz="0 0 0"
        rpy="0 0 0" />
      <geometry>
        <mesh
          filename="package://broken_feet/meshes/02.STL" />
      </geometry>
    </collision>
  </link>
  <joint
    name="31_32"
    type="revolute">
    <origin
      xyz="0 0 0.0812"
      rpy="0 0 0" />
    <parent
      link="31" />
    <child
      link="32" />
    <axis
      xyz="1 0 0" />
      <limit
      lower="-4"
      upper="4"
      effort="2"
      velocity="0.2094396" />
  </joint>
  <link
    name="camera">
    <inertial>
      <origin
        xyz="-6.93889390390723E-18 0 0.000999999999999994"
        rpy="0 0 0" />
      <mass
        value="0.05" />
      <inertia
        ixx="7.44492009053829E-11"
        ixy="3.39483796978698E-28"
        ixz="-4.06822130565541E-25"
        iyy="7.44492009053829E-11"
        iyz="3.87740912134232E-26"
        izz="1.22718463030851E-10" />
    </inertial>
    <visual>
      <origin
        xyz="0 0 0"
        rpy="0 0 0" />
      <geometry>
        <mesh
          filename="package://V000_cam/meshes/camera.STL" />
      </geometry>
      <material
        name="">
        <color
          rgba="0.2 0.2 0.2 1"  />
      </material>
    </visual>
    <collision>
      <origin
        xyz="0 0 0"
        rpy="0 0 0" />
      <geometry>
        <mesh
          filename="package://V000_cam/meshes/camera.STL" />
      </geometry>
    </collision>
  </link>
  <joint
    name="body_cam"
    type="fixed">
    <origin
      xyz="-0.0315000177857134 0.128467195926324 0.0788583994340782"
      rpy="-0.712309306 0 0" />
    <parent
      link="body" />
    <child
      link="camera" />
    <axis
      xyz="0 0 0" />
  </joint>
</robot>